Workbook

Sheet Door
H1: PROJECT NAME | I1: WLA - B13 | K1: GENERAL CONTRACTOR | M1: Walton Construction inc. | O1: DATE OF PREPARATION | Q1: =+TODAY() -> 46184
H2: LOCATIONS | K2: SUBCONTRACTOR | M2: KAPTIVE C&P
B4: Identification & Site Logic | H4: Technical Assessment Matrix | Y4: Pathology
B5: Photo | C5: Inspection Level | D5: Room Name | E5: Access Status | F5: ID Door | G5: Door Origin | H5: Door Type | I5: Door - Current Status | J5: Door Material | K5: Door - Recommended Action | L5: Door - Notes | M5: Frame - Current Status | N5: Frame - Recommended Action | O5: Frame - Notes | P5: Hinges - Current Status | Q5: Hinges - Recommended Action | R5: Transom - Current Status | S5: Transom - Function | T5: Transom - Recommended Action | U5: Transom - Notes | V5: Door handle - Current Status | W5: Door handle - Recommended Action | X5: Automatic closing arm - Current Status | Y5: Technical Notes | Z5: Evaluation score | AA5: Priority
C6: Basement Level | D6: MECH ROOM AND STORAGE | E6: Accessible | F6: D0001 | G6: Original Door | H6: Double Door | I6: Existing | J6: Metal | K6: Clear/Restore | L6: Tier 2 | M6: Existing | N6: Clear/Restore | P6: Existing | Q6: Clear/Restore | R6: Existing | S6: Not Operable | T6: Clear/Restore | U6: RFI if we putting glass or staying metal gate | V6: Missing | W6: Repair/Make | X6: None | Z6: 25 | AA6: =IF(Z6=0, "Not Verifiable", IF(Z6<=18, "Priority 1", IF(Z6<=29, "Priority 2", IF(Z6<=40, "Priority 3", "Priority 4")))) -> Priority 2
C7: Basement Level | D7: MECH ROOM AND STORAGE | E7: Accessible | F7: D0002 | G7: Original Door | H7: Single Door | I7: Missing | J7: Wood | K7: Repair/Make | L7: Door missing | M7: Existing | N7: Clear/Restore | P7: Missing | Q7: Repair/Make | R7: None | S7: Not Operable | T7: None | V7: Missing | W7: Repair/Make | X7: None | Y7: Door missing | Z7: 41 | AA7: =IF(Z7=0, "Not Verifiable", IF(Z7<=18, "Priority 1", IF(Z7<=29, "Priority 2", IF(Z7<=40, "Priority 3", "Priority 4")))) -> Priority 4
C8: Basement Level | D8: MECH ROOM AND STORAGE | E8: Accessible | F8: D0004 | G8: Original Door | H8: Single Door | I8: Existing | J8: Wood | K8: Clear/Restore | L8: Tier 3 Best | M8: Existing | N8: Clear/Restore | P8: Existing | Q8: Clear/Restore | R8: None | S8: Not Operable | T8: None | V8: Missing | W8: Repair/Make | X8: None | Z8: 21 | AA8: =IF(Z8=0, "Not Verifiable", IF(Z8<=18, "Priority 1", IF(Z8<=29, "Priority 2", IF(Z8<=40, "Priority 3", "Priority 4")))) -> Priority 2
C9: Basement Level | D9: MECH ROOM AND STORAGE | E9: Accessible | F9: D0005 | G9: Original Door | H9: Single Door | I9: Existing | J9: Wood | K9: Clear/Restore | L9: Tier 3 Best | M9: Existing | N9: Clear/Restore | P9: Existing | Q9: Clear/Restore | R9: None | S9: Not Operable | T9: None | V9: Missing | W9: Repair/Make | X9: None | Z9: 21 | AA9: =IF(Z9=0, "Not Verifiable", IF(Z9<=18, "Priority 1", IF(Z9<=29, "Priority 2", IF(Z9<=40, "Priority 3", "Priority 4")))) -> Priority 2
C10: Basement Level | D10: MECH ROOM AND STORAGE | E10: Accessible | F10: D0006 | G10: Original Door | H10: Single Door | I10: Existing | J10: Wood | K10: Repair/Make | L10: Tier 2 | M10: Missing | N10: Clear/Restore | P10: Existing | Q10: Clear/Restore | R10: None | S10: Not Operable | T10: None | V10: Missing | W10: Repair/Make | X10: None | Z10: 35 | AA10: =IF(Z10=0, "Not Verifiable", IF(Z10<=18, "Priority 1", IF(Z10<=29, "Priority 2", IF(Z10<=40, "Priority 3", "Priority 4")))) -> Priority 3
C11: Basement Level | D11: MECH ROOM AND STORAGE | E11: Accessible | F11: D0007 | G11: Not applicable | H11: Single Door | I11: Missing | J11: RFI closet not marked in the plans | K11: Repair/Make | L11: RFI | M11: Existing | N11: Clear/Restore | P11: Missing | Q11: Repair/Make | R11: None | S11: Not Operable | T11: None | V11: Missing | W11: Repair/Make | X11: None | Y11: RFI door frame no door and not in the plans | Z11: 41 | AA11: =IF(Z11=0, "Not Verifiable", IF(Z11<=18, "Priority 1", IF(Z11<=29, "Priority 2", IF(Z11<=40, "Priority 3", "Priority 4")))) -> Priority 4
C12: Basement Level | D12: MECH ROOM AND STORAGE | E12: Accessible | F12: D0008 | G12: Not applicable | H12: Single Door | I12: Missing | J12: Wood | K12: Repair/Make | L12: RFI door not in the plans | M12: Existing | N12: Clear/Restore | P12: Missing | Q12: Repair/Make | R12: None | S12: Not Operable | T12: None | V12: Missing | W12: Repair/Make | X12: None | Y12: RFI Door not in the plans | Z12: 41 | AA12: =IF(Z12=0, "Not Verifiable", IF(Z12<=18, "Priority 1", IF(Z12<=29, "Priority 2", IF(Z12<=40, "Priority 3", "Priority 4")))) -> Priority 4
C13: Basement Level | D13: MECH ROOM AND STORAGE | E13: Accessible | F13: D0009 | G13: Not applicable | H13: Single Door | I13: Missing | J13: Wood | K13: Repair/Make | L13: RFI Door not in the plans | M13: Existing | N13: Clear/Restore | P13: Missing | Q13: Repair/Make | R13: None | S13: Not Operable | T13: None | V13: Missing | W13: Repair/Make | X13: None | Y13: RFI Door not in the plans | Z13: 41 | AA13: =IF(Z13=0, "Not Verifiable", IF(Z13<=18, "Priority 1", IF(Z13<=29, "Priority 2", IF(Z13<=40, "Priority 3", "Priority 4")))) -> Priority 4
C14: Basement Level | D14: MECH ROOM AND STORAGE | E14: Accessible | F14: D0003 | G14: Original Door | H14: Single Door | I14: Existing | J14: Wood | K14: Clear/Restore | L14: Tier 2 | M14: Existing | N14: Clear/Restore | P14: Existing | Q14: Clear/Restore | R14: None | S14: Not Operable | T14: None | V14: Missing | W14: Repair/Make | X14: None | Z14: 21 | AA14: =IF(Z14=0, "Not Verifiable", IF(Z14<=18, "Priority 1", IF(Z14<=29, "Priority 2", IF(Z14<=40, "Priority 3", "Priority 4")))) -> Priority 2
C15: Level 1 | D15: CANTEEN AND PATRIOT STORE | E15: Accessible | F15: D1001 | G15: New Door | H15: Double Door | I15: Missing | J15: Metal | K15: Repair/Make | M15: Missing | N15: Repair/Make | P15: Missing | Q15: Repair/Make | R15: None | S15: Not Operable | T15: None | V15: Missing | W15: Repair/Make | X15: None | Y15: New door new everything | Z15: 52 | AA15: =IF(Z15=0, "Not Verifiable", IF(Z15<=18, "Priority 1", IF(Z15<=29, "Priority 2", IF(Z15<=40, "Priority 3", "Priority 4")))) -> Priority 4
C16: Level 1 | D16: FITNESS | E16: Accessible | F16: D1002 | G16: New Door | H16: Double Door | I16: Missing | J16: Metal | K16: Repair/Make | M16: Missing | N16: Repair/Make | P16: Missing | Q16: Repair/Make | R16: None | S16: Not Operable | T16: None | V16: Missing | W16: Repair/Make | X16: None | Z16: 52 | AA16: =IF(Z16=0, "Not Verifiable", IF(Z16<=18, "Priority 1", IF(Z16<=29, "Priority 2", IF(Z16<=40, "Priority 3", "Priority 4")))) -> Priority 4
C17: Level 1 | D17: GRAND HALL | E17: Accessible | F17: D1003 | G17: Original Door | H17: Double Door | I17: Missing | J17: Metal | K17: Repair/Make | M17: Missing | N17: Repair/Make | P17: Missing | Q17: Repair/Make | R17: None | S17: Not Operable | T17: None | V17: Missing | W17: Repair/Make | X17: None | Y17: New door new everything | Z17: 52 | AA17: =IF(Z17=0, "Not Verifiable", IF(Z17<=18, "Priority 1", IF(Z17<=29, "Priority 2", IF(Z17<=40, "Priority 3", "Priority 4")))) -> Priority 4
C18: Level 1 | D18: FITNESS | E18: Demolished or Lost | F18: D1004 | G18: New Door | Z18: 0 | AA18: =IF(Z18=0, "Not Verifiable", IF(Z18<=18, "Priority 1", IF(Z18<=29, "Priority 2", IF(Z18<=40, "Priority 3", "Priority 4")))) -> Not Verifiable
C19: Level 1 | D19: Other | E19: Accessible | F19: D1006 | G19: New Door | H19: Single Door | I19: Missing | J19: Wood | K19: Repair/Make | L19: Door missing | M19: Existing | N19: Clear/Restore | P19: Missing | Q19: Repair/Make | R19: Existing | S19: Not Operable | T19: Clear/Restore | V19: Missing | W19: Repair/Make | X19: None | Y19: Door is missing frame is there | Z19: 45 | AA19: =IF(Z19=0, "Not Verifiable", IF(Z19<=18, "Priority 1", IF(Z19<=29, "Priority 2", IF(Z19<=40, "Priority 3", "Priority 4")))) -> Priority 4
C20: Level 1 | D20: STORAGE | E20: Accessible | F20: D1009 | G20: Original Door | H20: Single Door | I20: Existing | J20: Wood | K20: Clear/Restore | L20: Tier 2 | M20: Existing | N20: Clear/Restore | P20: Missing | Q20: Repair/Make | R20: None | S20: Not Operable | T20: None | V20: Existing | W20: Clear/Restore | X20: None | Z20: 18 | AA20: =IF(Z20=0, "Not Verifiable", IF(Z20<=18, "Priority 1", IF(Z20<=29, "Priority 2", IF(Z20<=40, "Priority 3", "Priority 4")))) -> Priority 1
C21: Level 1 | D21: Other | E21: Accessible | F21: D1010 | G21: Original Door | H21: Single Door | I21: Existing | J21: Wood | K21: Repair/Make | M21: Existing | N21: Clear/Restore | P21: Existing | Q21: Clear/Restore | R21: None | S21: Not Operable | T21: None | V21: Missing | W21: Repair/Make | X21: None | Y21: New door needed. Door tier 1 | Z21: 26 | AA21: =IF(Z21=0, "Not Verifiable", IF(Z21<=18, "Priority 1", IF(Z21<=29, "Priority 2", IF(Z21<=40, "Priority 3", "Priority 4")))) -> Priority 2
C22: Level 1 | D22: MENS RESTROOM | E22: Demolished or Lost | F22: D1011 | G22: New Door | Y22: New door new everything | Z22: 0 | AA22: =IF(Z22=0, "Not Verifiable", IF(Z22<=18, "Priority 1", IF(Z22<=29, "Priority 2", IF(Z22<=40, "Priority 3", "Priority 4")))) -> Not Verifiable
C23: Level 1 | D23: MENS RESTROOM | E23: Demolished or Lost | F23: D1012 | G23: New Door | Y23: New door new everything | Z23: 0 | AA23: =IF(Z23=0, "Not Verifiable", IF(Z23<=18, "Priority 1", IF(Z23<=29, "Priority 2", IF(Z23<=40, "Priority 3", "Priority 4")))) -> Not Verifiable
C24: Level 1 | D24: MENS RESTROOM | E24: Demolished or Lost | F24: D1013 | G24: New Door | Y24: New door new everything | Z24: 0 | AA24: =IF(Z24=0, "Not Verifiable", IF(Z24<=18, "Priority 1", IF(Z24<=29, "Priority 2", IF(Z24<=40, "Priority 3", "Priority 4")))) -> Not Verifiable
C25: Level 1 | D25: MENS RESTROOM | E25: Demolished or Lost | F25: D1014 | G25: New Door | Y25: New door new everything | Z25: 0 | AA25: =IF(Z25=0, "Not Verifiable", IF(Z25<=18, "Priority 1", IF(Z25<=29, "Priority 2", IF(Z25<=40, "Priority 3", "Priority 4")))) -> Not Verifiable
C26: Level 1 | D26: MENS RESTROOM | E26: Demolished or Lost | F26: D1015 | G26: New Door | Y26: New door new everything | Z26: 0 | AA26: =IF(Z26=0, "Not Verifiable", IF(Z26<=18, "Priority 1", IF(Z26<=29, "Priority 2", IF(Z26<=40, "Priority 3", "Priority 4")))) -> Not Verifiable
C27: Level 1 | D27: MENS RESTROOM | E27: Demolished or Lost | F27: D1016 | G27: New Door | Y27: New door new everything | Z27: 0 | AA27: =IF(Z27=0, "Not Verifiable", IF(Z27<=18, "Priority 1", IF(Z27<=29, "Priority 2", IF(Z27<=40, "Priority 3", "Priority 4")))) -> Not Verifiable
C28: Level 1 | D28: Other | E28: Accessible | F28: D1017 | G28: Original Door | H28: Single Door | I28: Existing | J28: Wood | K28: Clear/Restore | M28: Existing | N28: Clear/Restore | P28: Existing | Q28: Clear/Restore | R28: None | S28: Not Operable | T28: None | V28: Existing | W28: Clear/Restore | X28: None | Z28: 12 | AA28: =IF(Z28=0, "Not Verifiable", IF(Z28<=18, "Priority 1", IF(Z28<=29, "Priority 2", IF(Z28<=40, "Priority 3", "Priority 4")))) -> Priority 1
C29: Level 1 | D29: EAST LOBBY | E29: Demolished or Lost | F29: D1019 | G29: New Door | Y29: New Door. Old one was remove. | Z29: 0 | AA29: =IF(Z29=0, "Not Verifiable", IF(Z29<=18, "Priority 1", IF(Z29<=29, "Priority 2", IF(Z29<=40, "Priority 3", "Priority 4")))) -> Not Verifiable
C30: Level 1 | D30: WEST LOBBY | E30: Demolished or Lost | F30: D1020 | G30: New Door | Y30: New door new everything | Z30: 0 | AA30: =IF(Z30=0, "Not Verifiable", IF(Z30<=18, "Priority 1", IF(Z30<=29, "Priority 2", IF(Z30<=40, "Priority 3", "Priority 4")))) -> Not Verifiable
C31: Level 1 | D31: EAST LOBBY | E31: Demolished or Lost | F31: D1021 | G31: New Door | Y31: New door new everything | Z31: 0 | AA31: =IF(Z31=0, "Not Verifiable", IF(Z31<=18, "Priority 1", IF(Z31<=29, "Priority 2", IF(Z31<=40, "Priority 3", "Priority 4")))) -> Not Verifiable
C32: Level 1 | D32: STORAGE | E32: Demolished or Lost | F32: D1022 | G32: New Door | Y32: New door. Opening has to be cut | Z32: 0 | AA32: =IF(Z32=0, "Not Verifiable", IF(Z32<=18, "Priority 1", IF(Z32<=29, "Priority 2", IF(Z32<=40, "Priority 3", "Priority 4")))) -> Not Verifiable
C33: Level 1 | D33: STORAGE | E33: Demolished or Lost | F33: D1023 | G33: New Door | Y33: New door new everything and opening needs to be cut | Z33: 0 | AA33: =IF(Z33=0, "Not Verifiable", IF(Z33<=18, "Priority 1", IF(Z33<=29, "Priority 2", IF(Z33<=40, "Priority 3", "Priority 4")))) -> Not Verifiable
C34: Level 1 | D34: ELEC | E34: Demolished or Lost | F34: D1024 | G34: New Door | Y34: New door new everything | Z34: 0 | AA34: =IF(Z34=0, "Not Verifiable", IF(Z34<=18, "Priority 1", IF(Z34<=29, "Priority 2", IF(Z34<=40, "Priority 3", "Priority 4")))) -> Not Verifiable
C35: Level 1 | D35: WOMENS RESTROOM | E35: Demolished or Lost | F35: D1025 | G35: New Door | Y35: New door new everything | Z35: 0 | AA35: =IF(Z35=0, "Not Verifiable", IF(Z35<=18, "Priority 1", IF(Z35<=29, "Priority 2", IF(Z35<=40, "Priority 3", "Priority 4")))) -> Not Verifiable
C36: Level 1 | D36: WOMENS RESTROOM | E36: Demolished or Lost | F36: D1026 | G36: New Door | Y36: New door new everything | Z36: 0 | AA36: =IF(Z36=0, "Not Verifiable", IF(Z36<=18, "Priority 1", IF(Z36<=29, "Priority 2", IF(Z36<=40, "Priority 3", "Priority 4")))) -> Not Verifiable
C37: Level 1 | D37: WEST LOBBY | E37: Demolished or Lost | F37: D1028 | G37: New Door | Y37: New door new everything | Z37: 0 | AA37: =IF(Z37=0, "Not Verifiable", IF(Z37<=18, "Priority 1", IF(Z37<=29, "Priority 2", IF(Z37<=40, "Priority 3", "Priority 4")))) -> Not Verifiable
C38: Level 1 | D38: WOMENS RESTROOM | E38: Demolished or Lost | F38: D1029 | G38: New Door | Y38: New door new everything | Z38: 0 | AA38: =IF(Z38=0, "Not Verifiable", IF(Z38<=18, "Priority 1", IF(Z38<=29, "Priority 2", IF(Z38<=40, "Priority 3", "Priority 4")))) -> Not Verifiable
C39: Level 1 | D39: WOMENS RESTROOM | E39: Demolished or Lost | F39: D1030 | G39: New Door | Y39: New door new everything | Z39: 0 | AA39: =IF(Z39=0, "Not Verifiable", IF(Z39<=18, "Priority 1", IF(Z39<=29, "Priority 2", IF(Z39<=40, "Priority 3", "Priority 4")))) -> Not Verifiable
C40: Level 1 | D40: WOMENS RESTROOM | E40: Demolished or Lost | F40: D1031 | G40: New Door | Y40: New door new everything | Z40: 0 | AA40: =IF(Z40=0, "Not Verifiable", IF(Z40<=18, "Priority 1", IF(Z40<=29, "Priority 2", IF(Z40<=40, "Priority 3", "Priority 4")))) -> Not Verifiable
... C48: Level 1 | D48: WOMENS RESTROOM | E48: Demolished or Lost | F48: D1039 | G48: New Door | Y48: New door new everything | Z48: 0 | AA48: =IF(Z48=0, "Not Verifiable", IF(Z48<=18, "Priority 1", IF(Z48<=29, "Priority 2", IF(Z48<=40, "Priority 3", "Priority 4")))) -> Not Verifiable
...

Sheet Qualification
A4: ID Door | B4: Door Origin | C4: Door Type | D4: Door - Current Status | E4: Door - Recommended Action | F4: Frame - Current Status | G4: Frame - Recommended Action | H4: Hinges - Current Status | I4: Hinges - Recommended Action | J4: Transom - Current Status | K4: Transom - Function | L4: Transom - Recommended Action | M4: Door handle - Current Status | N4: Door handle - Recommended Action | O4: Automatic closing arm - Current Status | P4: Total | Q4: Priority
A5: =+Door!F6 -> D0001 | B5: =+Door!G6 -> Original Door | C5: =+Door!H6 -> Double Door | D5: =IF(Door!I6="Missing", 9, 0) -> 0 | E5: =IF(Door!K6="Repair/Make", 9, IF(Door!K6="Clear/Restore", 4, 0)) -> 4 | F5: =IF(Door!M6 ="Missing", 9, 0) -> 0 | G5: =IF(Door!N6="Repair/Make", 4, IF(Door!N6="Clear/Restore", 2, 0)) -> 2 | H5: =IF(Door!P6="Missing", 4, 0) -> 0 | I5: =IF(Door!Q6="Repair/Make", 4, IF(Door!Q6="Clear/Restore", 2, 0)) -> 2 | J5: =IF(Door!R6="Missing", 9, 0) -> 0 | K5: =IF(Door!S6="Operable", 4, 0) -> 0 | L5: =IF(Door!T6="Repair/Make", 9, IF(Door!T6="Clear/Restore", 4, 0)) -> 4 | M5: =IF(Door!V6="Missing", 4, 0) -> 4 | N5: =IF(Door!W6="Repair/Make", 9, IF(Door!W6="Clear/Restore", 4, 0)) -> 9 | O5: =IF(Door!X6="Replace", 6, IF(Door!X6="Keep", 2, 0)) -> 0 | P5: =SUM(B5:O5) -> 25 | Q5: =IF(P5=0, "Not Verifiable", IF(P5<=18, "Priority 1", IF(P5<=29, "Priority 2", IF(P5<=40, "Priority 3", "Priority 4")))) -> Priority 2
A6: =+Door!F7 -> D0002 | B6: =+Door!G7 -> Original Door | C6: =+Door!H7 -> Single Door | D6: =IF(Door!I7="Missing", 9, 0) -> 9 | E6: =IF(Door!K7="Repair/Make", 9, IF(Door!K7="Clear/Restore", 4, 0)) -> 9 | F6: =IF(Door!M7 ="Missing", 9, 0) -> 0 | G6: =IF(Door!N7="Repair/Make", 4, IF(Door!N7="Clear/Restore", 2, 0)) -> 2 | H6: =IF(Door!P7="Missing", 4, 0) -> 4 | I6: =IF(Door!Q7="Repair/Make", 4, IF(Door!Q7="Clear/Restore", 2, 0)) -> 4 | J6: =IF(Door!R7="Missing", 9, 0) -> 0 | K6: =IF(Door!S7="Operable", 4, 0) -> 0 | L6: =IF(Door!T7="Repair/Make", 9, IF(Door!T7="Clear/Restore", 4, 0)) -> 0 | M6: =IF(Door!V7="Missing", 4, 0) -> 4 | N6: =IF(Door!W7="Repair/Make", 9, IF(Door!W7="Clear/Restore", 4, 0)) -> 9 | O6: =IF(Door!X7="Replace", 6, IF(Door!X7="Keep", 2, 0)) -> 0 | P6: =SUM(B6:O6) -> 41 | Q6: =IF(P6=0, "Not Verifiable", IF(P6<=18, "Priority 1", IF(P6<=29, "Priority 2", IF(P6<=40, "Priority 3", "Priority 4")))) -> Priority 4
A7: =+Door!F8 -> D0004 | B7: =+Door!G8 -> Original Door | C7: =+Door!H8 -> Single Door | D7: =IF(Door!I8="Missing", 9, 0) -> 0 | E7: =IF(Door!K8="Repair/Make", 9, IF(Door!K8="Clear/Restore", 4, 0)) -> 4 | F7: =IF(Door!M8 ="Missing", 9, 0) -> 0 | G7: =IF(Door!N8="Repair/Make", 4, IF(Door!N8="Clear/Restore", 2, 0)) -> 2 | H7: =IF(Door!P8="Missing", 4, 0) -> 0 | I7: =IF(Door!Q8="Repair/Make", 4, IF(Door!Q8="Clear/Restore", 2, 0)) -> 2 | J7: =IF(Door!R8="Missing", 9, 0) -> 0 | K7: =IF(Door!S8="Operable", 4, 0) -> 0 | L7: =IF(Door!T8="Repair/Make", 9, IF(Door!T8="Clear/Restore", 4, 0)) -> 0 | M7: =IF(Door!V8="Missing", 4, 0) -> 4 | N7: =IF(Door!W8="Repair/Make", 9, IF(Door!W8="Clear/Restore", 4, 0)) -> 9 | O7: =IF(Door!X8="Replace", 6, IF(Door!X8="Keep", 2, 0)) -> 0 | P7: =SUM(B7:O7) -> 21 | Q7: =IF(P7=0, "Not Verifiable", IF(P7<=18, "Priority 1", IF(P7<=29, "Priority 2", IF(P7<=40, "Priority 3", "Priority 4")))) -> Priority 2
A8: =+Door!F9 -> D0005 | B8: =+Door!G9 -> Original Door | C8: =+Door!H9 -> Single Door | D8: =IF(Door!I9="Missing", 9, 0) -> 0 | E8: =IF(Door!K9="Repair/Make", 9, IF(Door!K9="Clear/Restore", 4, 0)) -> 4 | F8: =IF(Door!M9 ="Missing", 9, 0) -> 0 | G8: =IF(Door!N9="Repair/Make", 4, IF(Door!N9="Clear/Restore", 2, 0)) -> 2 | H8: =IF(Door!P9="Missing", 4, 0) -> 0 | I8: =IF(Door!Q9="Repair/Make", 4, IF(Door!Q9="Clear/Restore", 2, 0)) -> 2 | J8: =IF(Door!R9="Missing", 9, 0) -> 0 | K8: =IF(Door!S9="Operable", 4, 0) -> 0 | L8: =IF(Door!T9="Repair/Make", 9, IF(Door!T9="Clear/Restore", 4, 0)) -> 0 | M8: =IF(Door!V9="Missing", 4, 0) -> 4 | N8: =IF(Door!W9="Repair/Make", 9, IF(Door!W9="Clear/Restore", 4, 0)) -> 9 | O8: =IF(Door!X9="Replace", 6, IF(Door!X9="Keep", 2, 0)) -> 0 | P8: =SUM(B8:O8) -> 21 | Q8: =IF(P8=0, "Not Verifiable", IF(P8<=18, "Priority 1", IF(P8<=29, "Priority 2", IF(P8<=40, "Priority 3", "Priority 4")))) -> Priority 2
A9: =+Door!F10 -> D0006 | B9: =+Door!G10 -> Original Door | C9: =+Door!H10 -> Single Door | D9: =IF(Door!I10="Missing", 9, 0) -> 0 | E9: =IF(Door!K10="Repair/Make", 9, IF(Door!K10="Clear/Restore", 4, 0)) -> 9 | F9: =IF(Door!M10 ="Missing", 9, 0) -> 9 | G9: =IF(Door!N10="Repair/Make", 4, IF(Door!N10="Clear/Restore", 2, 0)) -> 2 | H9: =IF(Door!P10="Missing", 4, 0) -> 0 | I9: =IF(Door!Q10="Repair/Make", 4, IF(Door!Q10="Clear/Restore", 2, 0)) -> 2 | J9: =IF(Door!R10="Missing", 9, 0) -> 0 | K9: =IF(Door!S10="Operable", 4, 0) -> 0 | L9: =IF(Door!T10="Repair/Make", 9, IF(Door!T10="Clear/Restore", 4, 0)) -> 0 | M9: =IF(Door!V10="Missing", 4, 0) -> 4 | N9: =IF(Door!W10="Repair/Make", 9, IF(Door!W10="Clear/Restore", 4, 0)) -> 9 | O9: =IF(Door!X10="Replace", 6, IF(Door!X10="Keep", 2, 0)) -> 0 | P9: =SUM(B9:O9) -> 35 | Q9: =IF(P9=0, "Not Verifiable", IF(P9<=18, "Priority 1", IF(P9<=29, "Priority 2", IF(P9<=40, "Priority 3", "Priority 4")))) -> Priority 3
A10: =+Door!F11 -> D0007 | B10: =+Door!G11 -> Not applicable | C10: =+Door!H11 -> Single Door | D10: =IF(Door!I11="Missing", 9, 0) -> 9 | E10: =IF(Door!K11="Repair/Make", 9, IF(Door!K11="Clear/Restore", 4, 0)) -> 9 | F10: =IF(Door!M11 ="Missing", 9, 0) -> 0 | G10: =IF(Door!N11="Repair/Make", 4, IF(Door!N11="Clear/Restore", 2, 0)) -> 2 | H10: =IF(Door!P11="Missing", 4, 0) -> 4 | I10: =IF(Door!Q11="Repair/Make", 4, IF(Door!Q11="Clear/Restore", 2, 0)) -> 4 | J10: =IF(Door!R11="Missing", 9, 0) -> 0 | K10: =IF(Door!S11="Operable", 4, 0) -> 0 | L10: =IF(Door!T11="Repair/Make", 9, IF(Door!T11="Clear/Restore", 4, 0)) -> 0 | M10: =IF(Door!V11="Missing", 4, 0) -> 4 | N10: =IF(Door!W11="Repair/Make", 9, IF(Door!W11="Clear/Restore", 4, 0)) -> 9 | O10: =IF(Door!X11="Replace", 6, IF(Door!X11="Keep", 2, 0)) -> 0 | P10: =SUM(B10:O10) -> 41 | Q10: =IF(P10=0, "Not Verifiable", IF(P10<=18, "Priority 1", IF(P10<=29, "Priority 2", IF(P10<=40, "Priority 3", "Priority 4")))) -> Priority 4
A11: =+Door!F12 -> D0008 | B11: =+Door!G12 -> Not applicable | C11: =+Door!H12 -> Single Door | D11: =IF(Door!I12="Missing", 9, 0) -> 9 | E11: =IF(Door!K12="Repair/Make", 9, IF(Door!K12="Clear/Restore", 4, 0)) -> 9 | F11: =IF(Door!M12 ="Missing", 9, 0) -> 0 | G11: =IF(Door!N12="Repair/Make", 4, IF(Door!N12="Clear/Restore", 2, 0)) -> 2 | H11: =IF(Door!P12="Missing", 4, 0) -> 4 | I11: =IF(Door!Q12="Repair/Make", 4, IF(Door!Q12="Clear/Restore", 2, 0)) -> 4 | J11: =IF(Door!R12="Missing", 9, 0) -> 0 | K11: =IF(Door!S12="Operable", 4, 0) -> 0 | L11: =IF(Door!T12="Repair/Make", 9, IF(Door!T12="Clear/Restore", 4, 0)) -> 0 | M11: =IF(Door!V12="Missing", 4, 0) -> 4 | N11: =IF(Door!W12="Repair/Make", 9, IF(Door!W12="Clear/Restore", 4, 0)) -> 9 | O11: =IF(Door!X12="Replace", 6, IF(Door!X12="Keep", 2, 0)) -> 0 | P11: =SUM(B11:O11) -> 41 | Q11: =IF(P11=0, "Not Verifiable", IF(P11<=18, "Priority 1", IF(P11<=29, "Priority 2", IF(P11<=40, "Priority 3", "Priority 4")))) -> Priority 4
A12: =+Door!F13 -> D0009 | B12: =+Door!G13 -> Not applicable | C12: =+Door!H13 -> Single Door | D12: =IF(Door!I13="Missing", 9, 0) -> 9 | E12: =IF(Door!K13="Repair/Make", 9, IF(Door!K13="Clear/Restore", 4, 0)) -> 9 | F12: =IF(Door!M13 ="Missing", 9, 0) -> 0 | G12: =IF(Door!N13="Repair/Make", 4, IF(Door!N13="Clear/Restore", 2, 0)) -> 2 | H12: =IF(Door!P13="Missing", 4, 0) -> 4 | I12: =IF(Door!Q13="Repair/Make", 4, IF(Door!Q13="Clear/Restore", 2, 0)) -> 4 | J12: =IF(Door!R13="Missing", 9, 0) -> 0 | K12: =IF(Door!S13="Operable", 4, 0) -> 0 | L12: =IF(Door!T13="Repair/Make", 9, IF(Door!T13="Clear/Restore", 4, 0)) -> 0 | M12: =IF(Door!V13="Missing", 4, 0) -> 4 | N12: =IF(Door!W13="Repair/Make", 9, IF(Door!W13="Clear/Restore", 4, 0)) -> 9 | O12: =IF(Door!X13="Replace", 6, IF(Door!X13="Keep", 2, 0)) -> 0 | P12: =SUM(B12:O12) -> 41 | Q12: =IF(P12=0, "Not Verifiable", IF(P12<=18, "Priority 1", IF(P12<=29, "Priority 2", IF(P12<=40, "Priority 3", "Priority 4")))) -> Priority 4
A13: =+Door!F14 -> D0003 | B13: =+Door!G14 -> Original Door | C13: =+Door!H14 -> Single Door | D13: =IF(Door!I14="Missing", 9, 0) -> 0 | E13: =IF(Door!K14="Repair/Make", 9, IF(Door!K14="Clear/Restore", 4, 0)) -> 4 | F13: =IF(Door!M14 ="Missing", 9, 0) -> 0 | G13: =IF(Door!N14="Repair/Make", 4, IF(Door!N14="Clear/Restore", 2, 0)) -> 2 | H13: =IF(Door!P14="Missing", 4, 0) -> 0 | I13: =IF(Door!Q14="Repair/Make", 4, IF(Door!Q14="Clear/Restore", 2, 0)) -> 2 | J13: =IF(Door!R14="Missing", 9, 0) -> 0 | K13: =IF(Door!S14="Operable", 4, 0) -> 0 | L13: =IF(Door!T14="Repair/Make", 9, IF(Door!T14="Clear/Restore", 4, 0)) -> 0 | M13: =IF(Door!V14="Missing", 4, 0) -> 4 | N13: =IF(Door!W14="Repair/Make", 9, IF(Door!W14="Clear/Restore", 4, 0)) -> 9 | O13: =IF(Door!X14="Replace", 6, IF(Door!X14="Keep", 2, 0)) -> 0 | P13: =SUM(B13:O13) -> 21 | Q13: =IF(P13=0, "Not Verifiable", IF(P13<=18, "Priority 1", IF(P13<=29, "Priority 2", IF(P13<=40, "Priority 3", "Priority 4")))) -> Priority 2
A14: =+Door!F15 -> D1001 | B14: =+Door!G15 -> New Door | C14: =+Door!H15 -> Double Door | D14: =IF(Door!I15="Missing", 9, 0) -> 9 | E14: =IF(Door!K15="Repair/Make", 9, IF(Door!K15="Clear/Restore", 4, 0)) -> 9 | F14: =IF(Door!M15 ="Missing", 9, 0) -> 9 | G14: =IF(Door!N15="Repair/Make", 4, IF(Door!N15="Clear/Restore", 2, 0)) -> 4 | H14: =IF(Door!P15="Missing", 4, 0) -> 4 | I14: =IF(Door!Q15="Repair/Make", 4, IF(Door!Q15="Clear/Restore", 2, 0)) -> 4 | J14: =IF(Door!R15="Missing", 9, 0) -> 0 | K14: =IF(Door!S15="Operable", 4, 0) -> 0 | L14: =IF(Door!T15="Repair/Make", 9, IF(Door!T15="Clear/Restore", 4, 0)) -> 0 | M14: =IF(Door!V15="Missing", 4, 0) -> 4 | N14: =IF(Door!W15="Repair/Make", 9, IF(Door!W15="Clear/Restore", 4, 0)) -> 9 | O14: =IF(Door!X15="Replace", 6, IF(Door!X15="Keep", 2, 0)) -> 0 | P14: =SUM(B14:O14) -> 52 | Q14: =IF(P14=0, "Not Verifiable", IF(P14<=18, "Priority 1", IF(P14<=29, "Priority 2", IF(P14<=40, "Priority 3", "Priority 4")))) -> Priority 4
A15: =+Door!F16 -> D1002 | B15: =+Door!G16 -> New Door | C15: =+Door!H16 -> Double Door | D15: =IF(Door!I16="Missing", 9, 0) -> 9 | E15: =IF(Door!K16="Repair/Make", 9, IF(Door!K16="Clear/Restore", 4, 0)) -> 9 | F15: =IF(Door!M16 ="Missing", 9, 0) -> 9 | G15: =IF(Door!N16="Repair/Make", 4, IF(Door!N16="Clear/Restore", 2, 0)) -> 4 | H15: =IF(Door!P16="Missing", 4, 0) -> 4 | I15: =IF(Door!Q16="Repair/Make", 4, IF(Door!Q16="Clear/Restore", 2, 0)) -> 4 | J15: =IF(Door!R16="Missing", 9, 0) -> 0 | K15: =IF(Door!S16="Operable", 4, 0) -> 0 | L15: =IF(Door!T16="Repair/Make", 9, IF(Door!T16="Clear/Restore", 4, 0)) -> 0 | M15: =IF(Door!V16="Missing", 4, 0) -> 4 | N15: =IF(Door!W16="Repair/Make", 9, IF(Door!W16="Clear/Restore", 4, 0)) -> 9 | O15: =IF(Door!X16="Replace", 6, IF(Door!X16="Keep", 2, 0)) -> 0 | P15: =SUM(B15:O15) -> 52 | Q15: =IF(P15=0, "Not Verifiable", IF(P15<=18, "Priority 1", IF(P15<=29, "Priority 2", IF(P15<=40, "Priority 3", "Priority 4")))) -> Priority 4
A16: =+Door!F17 -> D1003 | B16: =+Door!G17 -> Original Door | C16: =+Door!H17 -> Double Door | D16: =IF(Door!I17="Missing", 9, 0) -> 9 | E16: =IF(Door!K17="Repair/Make", 9, IF(Door!K17="Clear/Restore", 4, 0)) -> 9 | F16: =IF(Door!M17 ="Missing", 9, 0) -> 9 | G16: =IF(Door!N17="Repair/Make", 4, IF(Door!N17="Clear/Restore", 2, 0)) -> 4 | H16: =IF(Door!P17="Missing", 4, 0) -> 4 | I16: =IF(Door!Q17="Repair/Make", 4, IF(Door!Q17="Clear/Restore", 2, 0)) -> 4 | J16: =IF(Door!R17="Missing", 9, 0) -> 0 | K16: =IF(Door!S17="Operable", 4, 0) -> 0 | L16: =IF(Door!T17="Repair/Make", 9, IF(Door!T17="Clear/Restore", 4, 0)) -> 0 | M16: =IF(Door!V17="Missing", 4, 0) -> 4 | N16: =IF(Door!W17="Repair/Make", 9, IF(Door!W17="Clear/Restore", 4, 0)) -> 9 | O16: =IF(Door!X17="Replace", 6, IF(Door!X17="Keep", 2, 0)) -> 0 | P16: =SUM(B16:O16) -> 52 | Q16: =IF(P16=0, "Not Verifiable", IF(P16<=18, "Priority 1", IF(P16<=29, "Priority 2", IF(P16<=40, "Priority 3", "Priority 4")))) -> Priority 4
... A190: =+Door!F191 -> D2124 | B190: =+Door!G191 -> Not applicable | C190: =+Door!H191 -> Transom | D190: =IF(Door!I191="Missing", 9, 0) -> 0 | E190: =IF(Door!K191="Repair/Make", 9, IF(Door!K191="Clear/Restore", 4, 0)) -> 4 | F190: =IF(Door!M191 ="Missing", 9, 0) -> 0 | G190: =IF(Door!N191="Repair/Make", 4, IF(Door!N191="Clear/Restore", 2, 0)) -> 2 | H190: =IF(Door!P191="Missing", 4, 0) -> 0 | I190: =IF(Door!Q191="Repair/Make", 4, IF(Door!Q191="Clear/Restore", 2, 0)) -> 2 | J190: =IF(Door!R191="Missing", 9, 0) -> 0 | K190: =IF(Door!S191="Operable", 4, 0) -> 4 | L190: =IF(Door!T191="Repair/Make", 9, IF(Door!T191="Clear/Restore", 4, 0)) -> 4 | M190: =IF(Door!V191="Missing", 4, 0) -> 0 | N190: =IF(Door!W191="Repair/Make", 9, IF(Door!W191="Clear/Restore", 4, 0)) -> 4 | O190: =IF(Door!X191="Replace", 6, IF(Door!X191="Keep", 2, 0)) -> 0 | P190: =SUM(B190:O190) -> 20 | Q190: =IF(P190=0, "Not Verifiable", IF(P190<=18, "Priority 1", IF(P190<=29, "Priority 2", IF(P190<=40, "Priority 3", "Priority 4")))) -> Priority 2

Sheet Calculate
A2: Priority Type | B2: Total x Priority
A3: Priority 1 | B3: =+COUNTIF(Qualification!$Q$5:$Q$190,A3) -> 5
A4: Priority 2 | B4: =+COUNTIF(Qualification!$Q$5:$Q$190,A4) -> 37
A5: Priority 3 | B5: =+COUNTIF(Qualification!$Q$5:$Q$190,A5) -> 12
A6: Priority 4 | B6: =+COUNTIF(Qualification!$Q$5:$Q$190,A6) -> 13
A7: Not Verifiable | B7: =+COUNTIF(Qualification!$Q$5:$Q$190,A7) -> 119 | J7: 8
J8: 0
J10: 11
